Traceback (most recent call last):
  File "/home/smp17rjs/my_project_dir/.venv/lib/python3.12/site-packages/jupyter_cache/executors/utils.py", line 58, in single_nb_execution
    executenb(
  File "/home/smp17rjs/my_project_dir/.venv/lib/python3.12/site-packages/nbclient/client.py", line 1314, in execute
    return NotebookClient(nb=nb, resources=resources, km=km, **kwargs).execute()
           ^^^^^^^^^^^^^^^^^^^^^^^^^^^^^^^^^^^^^^^^^^^^^^^^^^^^^^^^^^^^^^^^^^^^^
  File "/home/smp17rjs/my_project_dir/.venv/lib/python3.12/site-packages/jupyter_core/utils/__init__.py", line 165, in wrapped
    return loop.run_until_complete(inner)
           ^^^^^^^^^^^^^^^^^^^^^^^^^^^^^^
  File "/usr/lib/python3.12/asyncio/base_events.py", line 687, in run_until_complete
    return future.result()
           ^^^^^^^^^^^^^^^
  File "/home/smp17rjs/my_project_dir/.venv/lib/python3.12/site-packages/nbclient/client.py", line 709, in async_execute
    await self.async_execute_cell(
  File "/home/smp17rjs/my_project_dir/.venv/lib/python3.12/site-packages/nbclient/client.py", line 1062, in async_execute_cell
    await self._check_raise_for_error(cell, cell_index, exec_reply)
  File "/home/smp17rjs/my_project_dir/.venv/lib/python3.12/site-packages/nbclient/client.py", line 918, in _check_raise_for_error
    raise CellExecutionError.from_cell_and_msg(cell, exec_reply_content)
nbclient.exceptions.CellExecutionError: An error occurred while executing the following cell:
------------------
````{prf:theorem} Whatever can go wrong will go wrong
:label: my-theorem

There is a non-zero probability that I have made a typo somewhere in ths theorem.

````
------------------


[0;36m  Cell [0;32mIn[1], line 1[0;36m[0m
[0;31m    ````{prf:theorem} Whatever can go wrong will go wrong[0m
[0m    ^[0m
[0;31mSyntaxError[0m[0;31m:[0m invalid syntax


